0707_11:57:00  | Traceback (most recent call last):
  File "D:\Users\hhp.DESKTOP-0MIJ0BM\AppData\Local\Programs\Python\Python37\lib\site-packages\urllib3\connection.py", line 175, in _new_conn    
    (self._dns_host, self.port), self.timeout, **extra_kw
  File "D:\Users\hhp.DESKTOP-0MIJ0BM\AppData\Local\Programs\Python\Python37\lib\site-packages\urllib3\util\connection.py", line 72, in create_connection
    for res in socket.getaddrinfo(host, port, family, socket.SOCK_STREAM):
  File "D:\Users\hhp.DESKTOP-0MIJ0BM\AppData\Local\Programs\Python\Python37\lib\socket.py", line 752, in getaddrinfo
    for res in _socket.getaddrinfo(host, port, family, type, proto, flags):
socket.gaierror: [Errno 11002] getaddrinfo failed

During handling of the above exception, another exception occurred:     

Traceback (most recent call last):
  File "D:\Users\hhp.DESKTOP-0MIJ0BM\AppData\Local\Programs\Python\Python37\lib\site-packages\urllib3\connectionpool.py", line 710, in urlopen  
    chunked=chunked,
  File "D:\Users\hhp.DESKTOP-0MIJ0BM\AppData\Local\Programs\Python\Python37\lib\site-packages\urllib3\connectionpool.py", line 398, in _make_request
    conn.request(method, url, **httplib_request_kw)
  File "D:\Users\hhp.DESKTOP-0MIJ0BM\AppData\Local\Programs\Python\Python37\lib\site-packages\urllib3\connection.py", line 239, in request      
    super(HTTPConnection, self).request(method, url, body=body, headers=headers)
  File "D:\Users\hhp.DESKTOP-0MIJ0BM\AppData\Local\Programs\Python\Python37\lib\http\client.py", line 1277, in request
    self._send_request(method, url, body, headers, encode_chunked)
  File "D:\Users\hhp.DESKTOP-0MIJ0BM\AppData\Local\Programs\Python\Python37\lib\http\client.py", line 1323, in _send_request
    self.endheaders(body, encode_chunked=encode_chunked)
  File "D:\Users\hhp.DESKTOP-0MIJ0BM\AppData\Local\Programs\Python\Python37\lib\http\client.py", line 1272, in endheaders
    self._send_output(message_body, encode_chunked=encode_chunked)      
  File "D:\Users\hhp.DESKTOP-0MIJ0BM\AppData\Local\Programs\Python\Python37\lib\http\client.py", line 1032, in _send_output
    self.send(msg)
  File "D:\Users\hhp.DESKTOP-0MIJ0BM\AppData\Local\Programs\Python\Python37\lib\http\client.py", line 972, in send
    self.connect()
  File "D:\Users\hhp.DESKTOP-0MIJ0BM\AppData\Local\Programs\Python\Python37\lib\site-packages\urllib3\connection.py", line 205, in connect      
    conn = self._new_conn()
  File "D:\Users\hhp.DESKTOP-0MIJ0BM\AppData\Local\Programs\Python\Python37\lib\site-packages\urllib3\connection.py", line 187, in _new_conn    
    self, "Failed to establish a new connection: %s" % e
urllib3.exceptions.NewConnectionError: <urllib3.connection.HTTPConnection object at 0x0000013D052FCE88>: Failed to establish a new connection: [Errno 11002] getaddrinfo failed

During handling of the above exception, another exception occurred:     

Traceback (most recent call last):
  File "D:\Users\hhp.DESKTOP-0MIJ0BM\AppData\Local\Programs\Python\Python37\lib\site-packages\requests\adapters.py", line 499, in send
    timeout=timeout,
  File "D:\Users\hhp.DESKTOP-0MIJ0BM\AppData\Local\Programs\Python\Python37\lib\site-packages\urllib3\connectionpool.py", line 786, in urlopen  
    method, url, error=e, _pool=self, _stacktrace=sys.exc_info()[2]     
  File "D:\Users\hhp.DESKTOP-0MIJ0BM\AppData\Local\Programs\Python\Python37\lib\site-packages\urllib3\util\retry.py", line 592, in increment    
    raise MaxRetryError(_pool, url, error or ResponseError(cause))
urllib3.exceptions.MaxRetryError: HTTPConnectionPool(host='data.taipower.com.tw', port=80): Max retries exceeded with url: /opendata01/apply/file/d006001/001.txt (Caused by NewConnectionError('<urllib3.connection.HTTPConnection object at 0x0000013D052FCE88>: Failed to establish a new connection: [Errno 11002] getaddrinfo failed'))

During handling of the above exception, another exception occurred:     

Traceback (most recent call last):
  File "d:/Users/hhp.DESKTOP-0MIJ0BM/Desktop/台電測試/python/TaiwanPowerOpenDataDownloader_Big5.py", line 123, in <module>
    schedule.run_pending()
  File "D:\Users\hhp.DESKTOP-0MIJ0BM\AppData\Local\Programs\Python\Python37\lib\site-packages\schedule\__init__.py", line 780, in run_pending   
    default_scheduler.run_pending()
  File "D:\Users\hhp.DESKTOP-0MIJ0BM\AppData\Local\Programs\Python\Python37\lib\site-packages\schedule\__init__.py", line 100, in run_pending   
    self._run_job(job)
  File "D:\Users\hhp.DESKTOP-0MIJ0BM\AppData\Local\Programs\Python\Python37\lib\site-packages\schedule\__init__.py", line 172, in _run_job      
    ret = job.run()
  File "D:\Users\hhp.DESKTOP-0MIJ0BM\AppData\Local\Programs\Python\Python37\lib\site-packages\schedule\__init__.py", line 661, in run
    ret = self.job_func()
  File "d:/Users/hhp.DESKTOP-0MIJ0BM/Desktop/台電測試/python/TaiwanPowerOpenDataDownloader_Big5.py", line 108, in check_file_exist
    download()
  File "d:/Users/hhp.DESKTOP-0MIJ0BM/Desktop/台電測試/python/TaiwanPowerOpenDataDownloader_Big5.py", line 23, in download
    res = requests.get(url)
  File "D:\Users\hhp.DESKTOP-0MIJ0BM\AppData\Local\Programs\Python\Python37\lib\site-packages\requests\api.py", line 73, in get
    return request("get", url, params=params, **kwargs)
  File "D:\Users\hhp.DESKTOP-0MIJ0BM\AppData\Local\Programs\Python\Python37\lib\site-packages\requests\api.py", line 59, in request
    return session.request(method=method, url=url, **kwargs)
  File "D:\Users\hhp.DESKTOP-0MIJ0BM\AppData\Local\Programs\Python\Python37\lib\site-packages\requests\sessions.py", line 587, in request
    resp = self.send(prep, **send_kwargs)
  File "D:\Users\hhp.DESKTOP-0MIJ0BM\AppData\Local\Programs\Python\Python37\lib\site-packages\requests\sessions.py", line 701, in send
    r = adapter.send(request, **kwargs)
  File "D:\Users\hhp.DESKTOP-0MIJ0BM\AppData\Local\Programs\Python\Python37\lib\site-packages\requests\adapters.py", line 565, in send
    raise ConnectionError(e, request=request)
requests.exceptions.ConnectionError: HTTPConnectionPool(host='data.taipower.com.tw', port=80): Max retries exceeded with url: /opendata01/apply/file/d006001/001.txt (Caused by NewConnectionError('<urllib3.connection.HTTPConnection object at 0x0000013D052FCE88>: Failed to establish a new connection: [Errno 11002] getaddrinfo failed'))